<?xml version="1.0"?>
<robot name="my_4dof_arm">

    <link name="world"/>

    <joint name="base_joint" type="fixed">
        <parent link="world"/>
        <child link="base_link"/>
        <origin xyz="0 0 0" rpy="0 0 0"/>
    </joint>

    <link name="base_link">
        <visual>
            <geometry>
                <cylinder length="0.1" radius="0.2"/>
            </geometry>
            <origin xyz="0 0 0.05" rpy="0 0 0"/>
            <material name="blue">
                <color rgba="0 0 0.8 1"/>
            </material>
        </visual>
    </link>

    <link name="shoulder_link">
        <visual>
            <geometry>
                <cylinder length="0.4" radius="0.05"/>
            </geometry>
            <origin xyz="0 0 0.2" rpy="0 0 0"/>
            <material name="red">
                <color rgba="0.8 0 0 1"/>
            </material>
        </visual>
    </link>

    <link name="elbow_link">
        <visual>
            <geometry>
                <cylinder length="0.4" radius="0.05"/>
            </geometry>
            <origin xyz="0 0 0.2" rpy="0 0 0"/>
            <material name="green">
                <color rgba="0 0.8 0 1"/>
            </material>
        </visual>
    </link>

    <link name="wrist_link">
        <visual>
            <geometry>
                <cylinder length="0.2" radius="0.05"/>
            </geometry>
            <origin xyz="0 0 0.1" rpy="0 0 0"/>
            <material name="yellow">
                <color rgba="0 0.8 0.8 1"/>
            </material>
        </visual>
    </link>

    <link name="base_rotate_link"/>
    
    <joint name="base_rotate_joint" type="revolute">
        <parent link="base_link"/>
        <child link="base_rotate_link"/>
        <origin xyz="0 0 0.1" rpy="0 0 0"/>
        <axis xyz="0 0 1"/>
        <limit lower="0" upper="3.14" effort="100" velocity="1"/>
    </joint>

    <joint name="shoulder_joint" type="revolute">
        <parent link="base_rotate_link"/>
        <child link="shoulder_link"/>
        <origin xyz="0 0 0" rpy="0 0 0"/>
        <axis xyz="0 1 0"/>
        <limit lower="-1.57" upper="1.57" effort="100" velocity="1"/>
    </joint>
    
    <joint name="elbow_joint" type="revolute">
        <parent link="shoulder_link"/>
        <child link="elbow_link"/>
        <origin xyz="0 0 0.4" rpy="0 0 0" />
        <axis xyz="0 1 0"/>
        <limit lower="-1.57" upper="1.57" effort="100" velocity="1"/>
    </joint>

    <joint name="wrist_joint" type="revolute">
        <parent link="elbow_link"/>
        <child link="wrist_link"/>
        <origin xyz="0 0 0.4" rpy="0 0 0" />
        <axis xyz="0 1 0"/>
        <limit lower="-1.57" upper="1.57" effort="100" velocity="1"/>
    </joint>

</robot>